# Copyright DataStax, Inc.
#
# Licensed under the Apache License, Version 2.0 (the "License");
# you may not use this file except in compliance with the License.
# You may obtain a copy of the License at
#
# http://www.apache.org/licenses/LICENSE-2.0
#
# Unless required by applicable law or agreed to in writing, software
# distributed under the License is distributed on an "AS IS" BASIS,
# WITHOUT WARRANTIES OR CONDITIONS OF ANY KIND, either express or implied.
# See the License for the specific language governing permissions and
# limitations under the License.

from __future__ import annotations

from dataclasses import dataclass
from typing import Any, Sequence

from astrapy.exceptions.data_api_exceptions import DataAPIException


@dataclass
class TooManyRowsToCountException(DataAPIException):
    """
    A `count_documents()` operation on a table failed because of the excessive amount
    of rows to count.

    Attributes:
        text: a text message about the exception.
    """

    text: str
    server_max_count_exceeded: bool

    def __init__(
        self,
        text: str,
        *,
        server_max_count_exceeded: bool,
    ) -> None:
        super().__init__(text)
        self.text = text
        self.server_max_count_exceeded = server_max_count_exceeded


@dataclass
class TableInsertManyException(DataAPIException):
    """
    An exception occurring within an insert_many (an operation that can span
    several requests). As such, it represents both the root error(s) that happened
    and information on the portion of the row that were successfully inserted.

    The behaviour of insert_many (concurrency and the `ordered` setting) make it
    possible that more than one "root errors" are collected.

    Attributes:
        inserted_ids: a list of the row IDs that have been successfully inserted,
            in the form of a dictionary matching the table primary key).
        inserted_id_tuples: the same information as for `inserted_ids` (in the same
            order), but in form of a tuples for each ID.
        exceptions: a list of the root exceptions leading to this error. The list,
            under normal circumstances, is not empty.
    """

    inserted_ids: list[Any]
    inserted_id_tuples: list[tuple[Any, ...]]
    exceptions: Sequence[Exception]

    def __str__(self) -> str:
        num_ids = len(self.inserted_ids)
        if self.exceptions:
            exc_desc: str
            excs_strs = [exc.__str__() for exc in self.exceptions[:8]]
            if len(self.exceptions) > 8:
                exc_desc = ", ".join(excs_strs) + " ... (more exceptions)"
            else:
                exc_desc = ", ".join(excs_strs)
            return (
                f"{self.__class__.__name__}({exc_desc} [with {num_ids} inserted ids])"
            )
        else:
            return f"{self.__class__.__name__}()"
